<?xml version="1.0" ?>
<robot name="four_legs" xmlns:xacro="http://ros.org/wiki/xacro">
    <!-- Material/Colors -->
    <material name="omni/Blue">
        <color rgba="0 0 0.8 1"/>
    </material>
    <material name="omni/Yellow">
        <color rgba="1 1 0 1"/>
    </material>
    <material name="omni/LightGrey">
        <color rgba="0.6 0.6 0.6 1"/>
    </material>

    <!-- Links/Joints -->
    <link name="base_link">
        <visual>
            <origin rpy="0 0 0" xyz="0 0 0.7"/>
            <geometry>
                <box size="1 0.3 0.2"/>
            </geometry>
            <material name="omni/LightGrey"/>
        </visual>

        <collision>
            <origin rpy="0 0 0" xyz="0 0 0.05715"/>
            <geometry>
                <box size="0.1143 0.0545 0.1143"/>
            </geometry>
        </collision>

        <inertial>
            <!-- CENTER OF MASS -->
            <origin rpy="0 0 0" xyz="0 0 0"/>
            <mass value="2"/>
            <!-- box inertia: 1/12*m(y^2+z^2), ... -->
            <inertia ixx="0.000267245666667" ixy="0" ixz="0" iyy="0.000435483" iyz="0" izz="0.000267245666667"/>
        </inertial>
    </link>
            <!-- left front leg -->
    <joint name="fleft_joint_1" type="continuous">
        <parent link="base_link"/>
        <child link="fleft_link_1"/>
        <limit effort="0" velocity="0"/>
        <origin rpy="0 -1 0" xyz="0.3 0.2 0.6"/>
        <axis xyz="0 1 0"/>
        <dynamics damping="0"/>
    </joint>

    <link name="fleft_link_1">
        <visual>
            <origin rpy="0 0 0" xyz="0 0 0"/>
            <geometry>
                <box size="0.3 0.1 0.1"/>
            </geometry>
            <material name="omni/Blue"/>
        </visual>

        <collision>
            <origin rpy="0 0 0" xyz="0 0 0"/>
            <geometry>
                <box size="0.3 0.1 0.1"/>
            </geometry>
        </collision>

        <inertial>
            <!-- CENTER OF MASS -->
            <origin rpy="0 0 0" xyz="0 0 0"/>
            <mass value="0.3"/>
            <!-- box inertia: 1/12*m(y^2+z^2), ... -->
            <inertia ixx="0.0835416666667" ixy="0" ixz="0" iyy="0.0834680033333" iyz="0" izz="0.000343003333333"/>
        </inertial>
    </link>

    <joint name="fleft_joint_2" type="continuous">
        <parent link="fleft_link_1"/>
        <child link="fleft_link_2"/>
        <limit effort="0" velocity="0"/>
        <origin rpy="0 -1.2 0" xyz="-0.18 0.1 -0.1"/>
        <axis xyz="0 1 0"/>
        <dynamics damping="0.2"/>
    </joint>

    <link name="fleft_link_2">
        <visual>
            <origin rpy="0 0 0" xyz="0 0 0"/>
            <geometry>
                <box size="0.3 0.1 0.1"/>
            </geometry>
            <material name="omni/Yellow"/>
        </visual>

        <collision>
            <origin rpy="0 0 0" xyz="0 0 0"/>
            <geometry>
                <box size="0.3 0.1 0.1"/>
            </geometry>
        </collision>

        <inertial>
            <!-- CENTER OF MASS -->
            <origin rpy="0 0 0" xyz="0 0 0"/>
            <mass value="0.2"/>
            <!-- box inertia: 1/12*m(y^2+z^2), ... -->
            <inertia ixx="0.0835416666667" ixy="0" ixz="0" iyy="0.0834680033333" iyz="0" izz="0.000343003333333"/>
        </inertial>
    </link>

        <joint name="fleft_joint_3" type="continuous">
        <parent link="fleft_link_2"/>
        <child link="fleft_link_3"/>
        <limit effort="0" velocity="0"/>
        <origin rpy="0 0.65 0" xyz="-0.23 0 -0.06"/>
        <axis xyz="0 -1 0"/>
        <dynamics damping="0.2"/>
    </joint>

    <link name="fleft_link_3">
        <visual>
            <origin rpy="0 0 0" xyz="0 0 0"/>
            <geometry>
                <box size="0.05 0.1 0.2"/>
            </geometry>
            <material name="omni/Blue"/>
        </visual>

        <collision>
            <origin rpy="0 0 0" xyz="0 0 0"/>
            <geometry>
                <box size="0.05 0.1 0.2"/>
            </geometry>
        </collision>

        <inertial>
            <!-- CENTER OF MASS -->
            <origin rpy="0 0 0" xyz="0 0 0"/>
            <mass value="0.05"/>
            <!-- box inertia: 1/12*m(y^2+z^2), ... -->
            <inertia ixx="0.0835416666667" ixy="0" ixz="0" iyy="0.0834680033333" iyz="0" izz="0.000343003333333"/>
        </inertial>
    </link>
            <!-- front right leg -->
    <joint name="fright_joint_1" type="continuous">
        <parent link="base_link"/>
        <child link="fright_link_1"/>
        <limit effort="0" velocity="0"/>
        <origin rpy="0 -1 0" xyz="0.3 -0.2 0.6"/>
        <axis xyz="0 1 0"/>
        <dynamics damping="0"/>
    </joint>

    <link name="fright_link_1">
        <visual>
            <origin rpy="0 0 0" xyz="0 0 0"/>
            <geometry>
                <box size="0.3 0.1 0.1"/>
            </geometry>
            <material name="omni/Blue"/>
        </visual>

        <collision>
            <origin rpy="0 0 0" xyz="0 0 0"/>
            <geometry>
                <box size="0.3 0.1 0.1"/>
            </geometry>
        </collision>

        <inertial>
            <!-- CENTER OF MASS -->
            <origin rpy="0 0 0" xyz="0 0 0"/>
            <mass value="0.3"/>
            <!-- box inertia: 1/12*m(y^2+z^2), ... -->
            <inertia ixx="0.0835416666667" ixy="0" ixz="0" iyy="0.0834680033333" iyz="0" izz="0.000343003333333"/>
        </inertial>
    </link>

    <joint name="fright_joint_2" type="continuous">
        <parent link="fright_link_1"/>
        <child link="fright_link_2"/>
        <limit effort="0" velocity="0"/>
        <origin rpy="0 -1.2 0" xyz="-0.18 -0.1 -0.1"/>
        <axis xyz="0 1 0"/>
        <dynamics damping="0.2"/>
    </joint>

    <link name="fright_link_2">
        <visual>
            <origin rpy="0 0 0" xyz="0 0 0"/>
            <geometry>
                <box size="0.3 0.1 0.1"/>
            </geometry>
            <material name="omni/Yellow"/>
        </visual>

        <collision>
            <origin rpy="0 0 0" xyz="0 0 0"/>
            <geometry>
                <box size="0.3 0.1 0.1"/>
            </geometry>
        </collision>

        <inertial>
            <!-- CENTER OF MASS -->
            <origin rpy="0 0 0" xyz="0 0 0"/>
            <mass value="0.2"/>
            <!-- box inertia: 1/12*m(y^2+z^2), ... -->
            <inertia ixx="0.0835416666667" ixy="0" ixz="0" iyy="0.0834680033333" iyz="0" izz="0.000343003333333"/>
        </inertial>
    </link>

        <joint name="fright_joint_3" type="continuous">
        <parent link="fright_link_2"/>
        <child link="fright_link_3"/>
        <limit effort="0" velocity="0"/>
        <origin rpy="0 0.65 0" xyz="-0.23 0 -0.06"/>
        <axis xyz="0 -1 0"/>
        <dynamics damping="0.2"/>
    </joint>

    <link name="fright_link_3">
        <visual>
            <origin rpy="0 0 0" xyz="0 0 0"/>
            <geometry>
                <box size="0.05 0.1 0.2"/>
            </geometry>
            <material name="omni/Blue"/>
        </visual>

        <collision>
            <origin rpy="0 0 0" xyz="0 0 0"/>
            <geometry>
                <box size="0.05 0.1 0.2"/>
            </geometry>
        </collision>

        <inertial>
            <!-- CENTER OF MASS -->
            <origin rpy="0 0 0" xyz="0 0 0"/>
            <mass value="0.05"/>
            <!-- box inertia: 1/12*m(y^2+z^2), ... -->
            <inertia ixx="0.0835416666667" ixy="0" ixz="0" iyy="0.0834680033333" iyz="0" izz="0.000343003333333"/>
        </inertial>
    </link>
          <!-- left back leg -->
    <joint name="bleft_joint_1" type="continuous">
        <parent link="base_link"/>
        <child link="bleft_link_1"/>
        <limit effort="0" velocity="0"/>
        <origin rpy="0 -1 0" xyz="-0.5 0.2 0.6"/>
        <axis xyz="0 1 0"/>
        <dynamics damping="0"/>
    </joint>

    <link name="bleft_link_1">
        <visual>
            <origin rpy="0 0 0" xyz="0 0 0"/>
            <geometry>
                <box size="0.3 0.1 0.1"/>
            </geometry>
            <material name="omni/Blue"/>
        </visual>

        <collision>
            <origin rpy="0 0 0" xyz="0 0 0"/>
            <geometry>
                <box size="0.3 0.1 0.1"/>
            </geometry>
        </collision>

        <inertial>
            <!-- CENTER OF MASS -->
            <origin rpy="0 0 0" xyz="0 0 0"/>
            <mass value="0.3"/>
            <!-- box inertia: 1/12*m(y^2+z^2), ... -->
            <inertia ixx="0.0835416666667" ixy="0" ixz="0" iyy="0.0834680033333" iyz="0" izz="0.000343003333333"/>
        </inertial>
    </link>

    <joint name="bleft_joint_2" type="continuous">
        <parent link="bleft_link_1"/>
        <child link="bleft_link_2"/>
        <limit effort="0" velocity="0"/>
        <origin rpy="0 -1.2 0" xyz="-0.18 0.1 -0.1"/>
        <axis xyz="0 1 0"/>
        <dynamics damping="0.2"/>
    </joint>

    <link name="bleft_link_2">
        <visual>
            <origin rpy="0 0 0" xyz="0 0 0"/>
            <geometry>
                <box size="0.3 0.1 0.1"/>
            </geometry>
            <material name="omni/Yellow"/>
        </visual>

        <collision>
            <origin rpy="0 0 0" xyz="0 0 0"/>
            <geometry>
                <box size="0.3 0.1 0.1"/>
            </geometry>
        </collision>

        <inertial>
            <!-- CENTER OF MASS -->
            <origin rpy="0 0 0" xyz="0 0 0"/>
            <mass value="0.2"/>
            <!-- box inertia: 1/12*m(y^2+z^2), ... -->
            <inertia ixx="0.0835416666667" ixy="0" ixz="0" iyy="0.0834680033333" iyz="0" izz="0.000343003333333"/>
        </inertial>
    </link>

        <joint name="bleft_joint_3" type="continuous">
        <parent link="bleft_link_2"/>
        <child link="bleft_link_3"/>
        <limit effort="0" velocity="0"/>
        <origin rpy="0 0.65 0" xyz="-0.23 0 -0.06"/>
        <axis xyz="0 -1 0"/>
        <dynamics damping="0.2"/>
    </joint>

    <link name="bleft_link_3">
        <visual>
            <origin rpy="0 0 0" xyz="0 0 0"/>
            <geometry>
                <box size="0.05 0.1 0.2"/>
            </geometry>
            <material name="omni/Blue"/>
        </visual>

        <collision>
            <origin rpy="0 0 0" xyz="0 0 0"/>
            <geometry>
                <box size="0.05 0.1 0.2"/>
            </geometry>
        </collision>

        <inertial>
            <!-- CENTER OF MASS -->
            <origin rpy="0 0 0" xyz="0 0 0"/>
            <mass value="0.05"/>
            <!-- box inertia: 1/12*m(y^2+z^2), ... -->
            <inertia ixx="0.0835416666667" ixy="0" ixz="0" iyy="0.0834680033333" iyz="0" izz="0.000343003333333"/>
        </inertial>
    </link>
            <!-- back right leg -->
    <joint name="bright_joint_1" type="continuous">
        <parent link="base_link"/>
        <child link="bright_link_1"/>
        <limit effort="0" velocity="0"/>
        <origin rpy="0 -1 0" xyz="-0.5 -0.2 0.6"/>
        <axis xyz="0 1 0"/>
        <dynamics damping="0"/>
    </joint>

    <link name="bright_link_1">
        <visual>
            <origin rpy="0 0 0" xyz="0 0 0"/>
            <geometry>
                <box size="0.3 0.1 0.1"/>
            </geometry>
            <material name="omni/Blue"/>
        </visual>

        <collision>
            <origin rpy="0 0 0" xyz="0 0 0"/>
            <geometry>
                <box size="0.3 0.1 0.1"/>
            </geometry>
        </collision>

        <inertial>
            <!-- CENTER OF MASS -->
            <origin rpy="0 0 0" xyz="0 0 0"/>
            <mass value="0.3"/>
            <!-- box inertia: 1/12*m(y^2+z^2), ... -->
            <inertia ixx="0.0835416666667" ixy="0" ixz="0" iyy="0.0834680033333" iyz="0" izz="0.000343003333333"/>
        </inertial>
    </link>

    <joint name="bright_joint_2" type="continuous">
        <parent link="bright_link_1"/>
        <child link="bright_link_2"/>
        <limit effort="0" velocity="0"/>
        <origin rpy="0 -1.2 0" xyz="-0.18 -0.1 -0.1"/>
        <axis xyz="0 1 0"/>
        <dynamics damping="0.2"/>
    </joint>

    <link name="bright_link_2">
        <visual>
            <origin rpy="0 0 0" xyz="0 0 0"/>
            <geometry>
                <box size="0.3 0.1 0.1"/>
            </geometry>
            <material name="omni/Yellow"/>
        </visual>

        <collision>
            <origin rpy="0 0 0" xyz="0 0 0"/>
            <geometry>
                <box size="0.3 0.1 0.1"/>
            </geometry>
        </collision>

        <inertial>
            <!-- CENTER OF MASS -->
            <origin rpy="0 0 0" xyz="0 0 0"/>
            <mass value="0.2"/>
            <!-- box inertia: 1/12*m(y^2+z^2), ... -->
            <inertia ixx="0.0835416666667" ixy="0" ixz="0" iyy="0.0834680033333" iyz="0" izz="0.000343003333333"/>
        </inertial>
    </link>

        <joint name="bright_joint_3" type="continuous">
        <parent link="bright_link_2"/>
        <child link="bright_link_3"/>
        <limit effort="0" velocity="0"/>
        <origin rpy="0 0.65 0" xyz="-0.23 0 -0.06"/>
        <axis xyz="0 -1 0"/>
        <dynamics damping="0.2"/>
    </joint>

    <link name="bright_link_3">
        <visual>
            <origin rpy="0 0 0" xyz="0 0 0"/>
            <geometry>
                <box size="0.05 0.1 0.2"/>
            </geometry>
            <material name="omni/Blue"/>
        </visual>

        <collision>
            <origin rpy="0 0 0" xyz="0 0 0"/>
            <geometry>
                <box size="0.05 0.1 0.2"/>
            </geometry>
        </collision>

        <inertial>
            <!-- CENTER OF MASS -->
            <origin rpy="0 0 0" xyz="0 0 0"/>
            <mass value="0.05"/>
            <!-- box inertia: 1/12*m(y^2+z^2), ... -->
            <inertia ixx="0.0835416666667" ixy="0" ixz="0" iyy="0.0834680033333" iyz="0" izz="0.000343003333333"/>
        </inertial>
    </link>
</robot>
